# Tasks: `vl53l0x_pigpio`実行時の`NameError`を修正

- [x] `src/vl53l0x_pigpio/__main__.py`に`save_config`をインポートする
- [x] `uv run vl53l0x_pigpio calibrate --distance 100` を実行して、エラーが解消されたことを確認する
- [x] リンターを実行して、コードの品質をチェックする